Workbook

Sheet Inputs
B2: Budget
B3: Total budget | C3: 280000
B5: Once-off costs
B6: Paint | C6: 0
B7: Building costs | C7: 55000
B8: Blender | C8: 4200
B9: Sandwich m | C9: 3300
B10: Fridge | C10: 13340
B11: Deposit | C11: 10000
B12: Registration | C12: 1000
B13: Cups | C13: 23989
B14: Cutlery | C14: 637
B15: Glasses | C15: 431.88
B16: Sit down cups | C16: =958+1258 -> 2216
B17: Branding | C17: 3050
B18: Lights | C18: 3185
B19: Website | C19: 303
B20: Health and Safety | C20: 7277
B21: Fire egstinguisher | C21: 2467
B22: Pest control | C22: 700
B23: Tablet | C23: 5000
B24: Yoco machine | C24: 2500
B25: Architect | C25: 8430
B26: Takeway cups - smoothi | C26: 6188
B27: Microwave | C27: 1800
B28: Chairs | C28: =600*8 -> 4800
B29: Tables | C29: =1700*4 -> 6800
B30: Umbrella | C30: =1800*2 -> 3600
B31: Sinage | C31: 5000
B32: Total | C32: =SUM(C7:C31) -> 175213.88
B34: Monthly costs
B35: Electrisity | C35: 3000
B36: Staff | C36: 20000 | E36: =800*2*4 -> 6400
B37: Generator | C37: 1500
B38: Insurance | C38: 800
B39: Coffee machine | C39: 2000
B40: Takeaway items | C40: 1000
B41: Gas | C41: 0
B42: Rent | C42: 10000
B43: Total | C43: =SUM(C35:C42) -> 38300
...

Sheet Coffee and food
A1: Coffee
B2: Price of cup of coffee
B3: Beans | C3: 24 | D3: =C3*Inputs!E55 -> 6.36
B4: Milk | C4: 270 | D4: =C4*Inputs!E56 -> 3.888 | G4: Reserves build up to pay for | I4: coffee
B5: Cups | C5: 1 | D5: =C5*Inputs!E57 -> 3.9148333 | I5: milk
B6: Total | D6: =SUM(D3:D5) -> 14.162833 | I6: cups
G7: Lag of coffee sales to account
B8: Selling price | C8: =Inputs!C60 -> 32 | G8: Discount
B9: Discount price | C9: =C8*(1-Inputs!C61) -> 24
B11: Sugar
B12: Price of sugar | C12: =Inputs!E58 -> 0.45
B13: % people using sugar | C13: 0.5
B15: Daily factor | C15: 8.5
B17: Daily view
B18: Month | C18: =EOMONTH(C20,0) -> 45046 | D18: =EOMONTH(D20,0) -> 45046 | E18: =EOMONTH(E20,0) -> 45046 | F18: =EOMONTH(F20,0) -> 45046 | G18: =EOMONTH(G20,0) -> 45046 | H18: =EOMONTH(H20,0) -> 45046 | I18: =EOMONTH(I20,0) -> 45046 | J18: =EOMONTH(J20,0) -> 45046 | ... XQ18: =EOMONTH(XQ20,0) -> 45657
B19: Day of the week | C19: Monday | D19: Tuesday | E19: Wednesday | F19: Thursday | G19: Friday | H19: Saturday | I19: Sunday | J19: Monday | K19: Tuesday | L19: Wednesday | M19: Thursday | N19: Friday | O19: Saturday | P19: Sunday | Q19: Monday | R19: Tuesday | S19: Wednesday | T19: Thursday | U19: Friday | V19: Saturday | W19: Sunday | X19: Monday | Y19: Tuesday | Z19: Wednesday | AA19: Thursday | AB19: Friday | AC19: Saturday | AD19: Sunday | AE19: Monday | AF19: Tuesday | AG19: Wednesday | AH19: Thursday | AI19: Friday | AJ19: Saturday | AK19: Sunday | AL19: Monday | AM19: Tuesday | AN19: Wednesday | AO19: Thursday | AP19: Friday | AQ19: Saturday | AR19: Sunday | AS19: Monday | AT19: Tuesday | AU19: Wednesday | AV19: Thursday | AW19: Friday | AX19: Saturday | AY19: Sunday | AZ19: Monday | BA19: Tuesday | BB19: Wednesday | BC19: Thursday | BD19: Friday | BE19: Saturday | BF19: Sunday | BG19: Monday | BH19: Tuesday | BI19: Wednesday | BJ19: Thursday | BK19: Friday | BL19: Saturday | BM19: Sunday | BN19: Monday | BO19: Tuesday | BP19: Wednesday | BQ19: Thursday | BR19: Friday | BS19: Saturday | BT19: Sunday | BU19: Monday | BV19: Tuesday | BW19: Wednesday | BX19: Thursday | BY19: Friday | BZ19: Saturday | CA19: Sunday | CB19: Monday | CC19: Tuesday | CD19: Wednesday | CE19: Thursday | CF19: Friday | CG19: Saturday | CH19: Sunday | CI19: Monday | CJ19: Tuesday | CK19: Wednesday | CL19: Thursday | CM19: Friday | CN19: Saturday | CO19: Sunday | CP19: Monday | CQ19: Tuesday | CR19: Wednesday | CS19: Thursday | CT19: Friday | CU19: Saturday | CV19: Sunday | CW19: Monday | CX19: Tuesday | CY19: Wednesday | CZ19: Thursday | DA19: Friday | DB19: Saturday | DC19: Sunday | DD19: Monday | DE19: Tuesday | DF19: Wednesday | DG19: Thursday | DH19: Friday | DI19: Saturday | DJ19: Sunday | DK19: Monday | DL19: Tuesday | DM19: Wednesday | DN19: Thursday | DO19: Friday | DP19: Saturday | DQ19: Sunday | DR19: Monday | DS19: Tuesday | DT19: Wednesday | DU19: Thursday | DV19: Friday | DW19: Saturday | DX19: Sunday | DY19: Monday | DZ19: Tuesday | EA19: Wednesday | EB19: Thursday | EC19: Friday | ED19: Saturday | EE19: Sunday | EF19: Monday | EG19: Tuesday | EH19: Wednesday | EI19: Thursday | EJ19: Friday | EK19: Saturday | EL19: Sunday | EM19: Monday | EN19: Tuesday | EO19: Wednesday | EP19: Thursday | EQ19: Friday | ER19: Saturday | ES19: Sunday | ET19: Monday | EU19: Tuesday | EV19: Wednesday | EW19: Thursday | EX19: Friday | EY19: Saturday | EZ19: Sunday | FA19: Monday | FB19: Tuesday | FC19: Wednesday | FD19: Thursday | FE19: Friday | FF19: Saturday | FG19: Sunday | FH19: Monday | FI19: Tuesday | FJ19: Wednesday | FK19: Thursday | FL19: Friday | FM19: Saturday | FN19: Sunday | FO19: Monday | FP19: Tuesday | FQ19: Wednesday | FR19: Thursday | FS19: Friday | FT19: Saturday | FU19: Sunday | FV19: Monday | FW19: Tuesday | FX19: Wednesday | FY19: Thursday | FZ19: Friday | GA19: Saturday | GB19: Sunday | GC19: Monday | GD19: Tuesday | GE19: Wednesday | GF19: Thursday | GG19: Friday | GH19: Saturday | GI19: Sunday | GJ19: Monday | GK19: Tuesday | GL19: Wednesday | GM19: Thursday | GN19: Friday | GO19: Saturday | GP19: Sunday | GQ19: Monday | GR19: Tuesday | GS19: Wednesday | GT19: Thursday | GU19: Friday | GV19: Saturday | GW19: Sunday | GX19: Monday | GY19: Tuesday | GZ19: Wednesday | HA19: Thursday | HB19: Friday | HC19: Saturday | HD19: Sunday | HE19: Monday | HF19: Tuesday | HG19: Wednesday | HH19: Thursday | HI19: Friday | HJ19: Saturday | HK19: Sunday | HL19: Monday | HM19: Tuesday | HN19: Wednesday | HO19: Thursday | HP19: Friday | HQ19: Saturday | HR19: Sunday | HS19: Monday | HT19: Tuesday | HU19: Wednesday | HV19: Thursday | HW19: Friday | HX19: Saturday | HY19: Sunday | HZ19: Monday | IA19: Tuesday | IB19: Wednesday | IC19: Thursday | ID19: Friday | IE19: Saturday | IF19: Sunday | IG19: Monday | IH19: Tuesday | II19: Wednesday | IJ19: Thursday | IK19: Friday | IL19: Saturday | IM19: Sunday | IN19: Monday | IO19: Tuesday | IP19: Wednesday | IQ19: Thursday | IR19: Friday | IS19: Saturday | IT19: Sunday | IU19: Monday | IV19: Tuesday | IW19: Wednesday | IX19: Thursday | IY19: Friday | IZ19: Saturday | JA19: Sunday | JB19: Monday | JC19: Tuesday | JD19: Wednesday | JE19: Thursday | JF19: Friday | JG19: Saturday | JH19: Sunday | JI19: Monday | JJ19: Tuesday | JK19: Wednesday | JL19: Thursday | JM19: Friday | JN19: Saturday | JO19: Sunday | JP19: Sunday | JQ19: Sunday | JR19: Sunday | JS19: Sunday | JT19: Sunday | JU19: Sunday | JV19: Sunday | JW19: Sunday | JX19: Sunday | JY19: Sunday | JZ19: Sunday | KA19: Sunday | KB19: Sunday | KC19: Sunday | KD19: Sunday | KE19: Sunday | KF19: Sunday | KG19: Sunday | KH19: Sunday | KI19: Sunday | KJ19: Sunday | KK19: Sunday | KL19: Sunday | KM19: Sunday | KN19: Sunday | KO19: Sunday | KP19: Sunday | KQ19: Sunday | KR19: Sunday | KS19: Sunday | KT19: Sunday | KU19: Sunday | KV19: Sunday | KW19: Sunday | KX19: Sunday | KY19: Sunday | KZ19: Sunday | LA19: Sunday | LB19: Sunday | LC19: Sunday | LD19: Sunday | LE19: Sunday | LF19: Sunday | LG19: Sunday | LH19: Sunday | LI19: Sunday | LJ19: Sunday | LK19: Sunday | LL19: Sunday | LM19: Sunday | LN19: Sunday | LO19: Sunday | LP19: Sunday | LQ19: Sunday | LR19: Sunday | LS19: Sunday | LT19: Sunday | LU19: Sunday | LV19: Sunday | LW19: Sunday | LX19: Sunday | LY19: Sunday | LZ19: Sunday | MA19: Sunday | MB19: Sunday | MC19: Sunday | MD19: Sunday | ME19: Sunday | MF19: Sunday | MG19: Sunday | MH19: Sunday | MI19: Sunday | MJ19: Sunday | MK19: Sunday | ML19: Sunday | MM19: Sunday | MN19: Sunday | MO19: Sunday | MP19: Sunday | MQ19: Sunday | MR19: Sunday | MS19: Sunday | MT19: Sunday | MU19: Sunday | MV19: Sunday | MW19: Sunday | MX19: Sunday | MY19: Sunday | MZ19: Sunday | NA19: Sunday | NB19: Sunday | NC19: Sunday | ND19: Sunday | NE19: Sunday | NF19: Sunday | NG19: Sunday | NH19: Sunday | NI19: Sunday | NJ19: Sunday | NK19: Sunday | NL19: Sunday | NM19: Sunday | NN19: Sunday | NO19: Sunday | NP19: Sunday | NQ19: Sunday | NR19: Sunday | NS19: Sunday | NT19: Sunday | NU19: Sunday | NV19: Sunday | NW19: Sunday | NX19: Sunday | NY19: Sunday | NZ19: Sunday | OA19: Sunday | OB19: Sunday | OC19: Sunday | OD19: Sunday | OE19: Sunday | OF19: Sunday | OG19: Sunday | OH19: Sunday | OI19: Sunday | OJ19: Sunday | OK19: Sunday | OL19: Sunday | OM19: Sunday | ON19: Sunday | OO19: Sunday | OP19: Sunday | OQ19: Sunday | OR19: Sunday | OS19: Sunday | OT19: Sunday | OU19: Sunday | OV19: Sunday | OW19: Sunday | OX19: Sunday | OY19: Sunday | OZ19: Sunday | PA19: Sunday | PB19: Sunday | PC19: Sunday | PD19: Sunday | PE19: Sunday | PF19: Sunday | PG19: Sunday | PH19: Sunday | PI19: Sunday | PJ19: Sunday | PK19: Sunday | PL19: Sunday | PM19: Sunday | PN19: Sunday | PO19: Sunday | PP19: Sunday | PQ19: Sunday | PR19: Sunday | PS19: Sunday | PT19: Sunday | PU19: Sunday | PV19: Sunday | PW19: Sunday | PX19: Sunday | PY19: Sunday | PZ19: Sunday | QA19: Sunday | QB19: Sunday | QC19: Sunday | QD19: Sunday | QE19: Sunday | QF19: Sunday | QG19: Sunday | QH19: Sunday | QI19: Sunday | QJ19: Sunday | QK19: Sunday | QL19: Sunday | QM19: Sunday | QN19: Sunday | QO19: Sunday | QP19: Sunday | QQ19: Sunday | QR19: Sunday | QS19: Sunday | QT19: Sunday | QU19: Sunday | QV19: Sunday | QW19: Sunday | QX19: Sunday | QY19: Sunday | QZ19: Sunday | RA19: Sunday | RB19: Sunday | RC19: Sunday | RD19: Sunday | RE19: Sunday | RF19: Sunday | RG19: Sunday | RH19: Sunday | RI19: Sunday | RJ19: Sunday | RK19: Sunday | RL19: Sunday | RM19: Sunday | RN19: Sunday | RO19: Sunday | RP19: Sunday | RQ19: Sunday | RR19: Sunday | RS19: Sunday | RT19: Sunday | RU19: Sunday | RV19: Sunday | RW19: Sunday | RX19: Sunday | RY19: Sunday | RZ19: Sunday | SA19: Sunday | SB19: Sunday | SC19: Sunday | SD19: Sunday | SE19: Sunday | SF19: Sunday | SG19: Sunday | SH19: Sunday | SI19: Sunday | SJ19: Sunday | SK19: Sunday | SL19: Sunday | SM19: Sunday | SN19: Sunday | SO19: Sunday | SP19: Sunday | SQ19: Sunday | SR19: Sunday | SS19: Sunday | ST19: Sunday | SU19: Sunday | SV19: Sunday | SW19: Sunday | SX19: Sunday | SY19: Sunday | SZ19: Sunday | TA19: Sunday | TB19: Sunday | TC19: Sunday | TD19: Sunday | TE19: Sunday | TF19: Sunday | TG19: Sunday | TH19: Sunday | TI19: Sunday | TJ19: Sunday | TK19: Sunday | TL19: Sunday | TM19: Sunday | TN19: Sunday | TO19: Sunday | TP19: Sunday | TQ19: Sunday | TR19: Sunday | TS19: Sunday | TT19: Sunday | TU19: Sunday | TV19: Sunday | TW19: Sunday | TX19: Sunday | TY19: Sunday | TZ19: Sunday | UA19: Sunday | UB19: Sunday | UC19: Sunday | UD19: Sunday | UE19: Sunday | UF19: Sunday | UG19: Sunday | UH19: Sunday | UI19: Sunday | UJ19: Sunday | UK19: Sunday | UL19: Sunday | UM19: Sunday | UN19: Sunday | UO19: Sunday | UP19: Sunday | UQ19: Sunday | UR19: Sunday | US19: Sunday | UT19: Sunday | UU19: Sunday | UV19: Sunday | UW19: Sunday | UX19: Sunday | UY19: Sunday | UZ19: Sunday | VA19: Sunday | VB19: Sunday | VC19: Sunday | VD19: Sunday | VE19: Sunday | VF19: Sunday | VG19: Sunday | VH19: Sunday | VI19: Sunday | VJ19: Sunday | VK19: Sunday | VL19: Sunday | VM19: Sunday | VN19: Sunday | VO19: Sunday | VP19: Sunday | VQ19: Sunday | VR19: Sunday | VS19: Sunday | VT19: Sunday | VU19: Sunday | VV19: Sunday | VW19: Sunday | VX19: Sunday | VY19: Sunday | VZ19: Sunday | WA19: Sunday | WB19: Sunday | WC19: Sunday | WD19: Sunday | WE19: Sunday | WF19: Sunday | WG19: Sunday | WH19: Sunday | WI19: Sunday | WJ19: Sunday | WK19: Sunday | WL19: Sunday | WM19: Sunday | WN19: Sunday | WO19: Sunday | WP19: Sunday | WQ19: Sunday | WR19: Sunday | WS19: Sunday | WT19: Sunday | WU19: Sunday | WV19: Sunday | WW19: Sunday | WX19: Sunday | WY19: Sunday | WZ19: Sunday | XA19: Sunday | XB19: Sunday | XC19: Sunday | XD19: Sunday | XE19: Sunday | XF19: Sunday | XG19: Sunday | XH19: Sunday | XI19: Sunday | XJ19: Sunday | XK19: Sunday | XL19: Sunday | XM19: Sunday | XN19: Sunday | XO19: Sunday | XP19: Sunday | XQ19: Sunday
B20: Exact date | C20: 45019 | D20: 45020 | E20: 45021 | F20: 45022 | G20: 45023 | H20: 45024 | I20: 45025 | J20: 45026 | K20: 45027 | L20: 45028 | M20: 45029 | N20: 45030 | O20: 45031 | P20: 45032 | Q20: 45033 | R20: 45034 | S20: 45035 | T20: 45036 | U20: 45037 | V20: 45038 | W20: 45039 | X20: 45040 | Y20: 45041 | Z20: 45042 | AA20: 45043 | AB20: 45044 | AC20: 45045 | AD20: 45046 | AE20: 45047 | AF20: 45048 | AG20: 45049 | AH20: 45050 | AI20: 45051 | AJ20: 45052 | AK20: 45053 | AL20: 45054 | AM20: 45055 | AN20: 45056 | AO20: 45057 | AP20: 45058 | AQ20: 45059 | AR20: 45060 | AS20: 45061 | AT20: 45062 | AU20: 45063 | AV20: 45064 | AW20: 45065 | AX20: 45066 | AY20: 45067 | AZ20: 45068 | BA20: 45069 | BB20: 45070 | BC20: 45071 | BD20: 45072 | BE20: 45073 | BF20: 45074 | BG20: 45075 | BH20: 45076 | BI20: 45077 | BJ20: 45078 | BK20: 45079 | BL20: 45080 | BM20: 45081 | BN20: 45082 | BO20: 45083 | BP20: 45084 | BQ20: 45085 | BR20: 45086 | BS20: 45087 | BT20: 45088 | BU20: 45089 | BV20: 45090 | BW20: 45091 | BX20: 45092 | BY20: 45093 | BZ20: 45094 | CA20: 45095 | CB20: 45096 | CC20: 45097 | CD20: 45098 | CE20: 45099 | CF20: 45100 | CG20: 45101 | CH20: 45102 | CI20: 45103 | CJ20: 45104 | CK20: 45105 | CL20: 45106 | CM20: 45107 | CN20: 45108 | CO20: 45109 | CP20: 45110 | CQ20: 45111 | CR20: 45112 | CS20: 45113 | CT20: 45114 | CU20: 45115 | CV20: 45116 | CW20: 45117 | CX20: 45118 | CY20: 45119 | CZ20: 45120 | DA20: 45121 | DB20: 45122 | DC20: 45123 | DD20: 45124 | DE20: 45125 | DF20: 45126 | DG20: 45127 | DH20: 45128 | DI20: 45129 | DJ20: 45130 | DK20: 45131 | DL20: 45132 | DM20: 45133 | DN20: 45134 | DO20: 45135 | DP20: 45136 | DQ20: 45137 | DR20: 45138 | DS20: 45139 | DT20: 45140 | DU20: 45141 | DV20: 45142 | DW20: 45143 | DX20: 45144 | DY20: 45145 | DZ20: 45146 | EA20: 45147 | EB20: 45148 | EC20: 45149 | ED20: 45150 | EE20: 45151 | EF20: 45152 | EG20: 45153 | EH20: 45154 | EI20: 45155 | EJ20: 45156 | EK20: 45157 | EL20: 45158 | EM20: 45159 | EN20: 45160 | EO20: 45161 | EP20: 45162 | EQ20: 45163 | ER20: 45164 | ES20: 45165 | ET20: 45166 | EU20: 45167 | EV20: 45168 | EW20: 45169 | EX20: 45170 | EY20: 45171 | EZ20: 45172 | FA20: 45173 | FB20: 45174 | FC20: 45175 | FD20: 45176 | FE20: 45177 | FF20: 45178 | FG20: 45179 | FH20: 45180 | FI20: 45181 | FJ20: 45182 | FK20: 45183 | FL20: 45184 | FM20: 45185 | FN20: 45186 | FO20: 45187 | FP20: 45188 | FQ20: 45189 | FR20: 45190 | FS20: 45191 | FT20: 45192 | FU20: 45193 | FV20: 45194 | FW20: 45195 | FX20: 45196 | FY20: 45197 | FZ20: 45198 | GA20: 45199 | GB20: 45200 | GC20: 45201 | GD20: 45202 | GE20: 45203 | GF20: 45204 | GG20: 45205 | GH20: 45206 | GI20: 45207 | GJ20: 45208 | GK20: 45209 | GL20: 45210 | GM20: 45211 | GN20: 45212 | GO20: 45213 | GP20: 45214 | GQ20: 45215 | GR20: 45216 | GS20: 45217 | GT20: 45218 | GU20: 45219 | GV20: 45220 | GW20: 45221 | GX20: 45222 | GY20: 45223 | GZ20: 45224 | HA20: 45225 | HB20: 45226 | HC20: 45227 | HD20: 45228 | HE20: 45229 | HF20: 45230 | HG20: 45231 | HH20: 45232 | HI20: 45233 | HJ20: 45234 | HK20: 45235 | HL20: 45236 | HM20: 45237 | HN20: 45238 | HO20: 45239 | HP20: 45240 | HQ20: 45241 | HR20: 45242 | HS20: 45243 | HT20: 45244 | HU20: 45245 | HV20: 45246 | HW20: 45247 | HX20: 45248 | HY20: 45249 | HZ20: 45250 | IA20: 45251 | IB20: 45252 | IC20: 45253 | ID20: 45254 | IE20: 45255 | IF20: 45256 | IG20: 45257 | IH20: 45258 | II20: 45259 | IJ20: 45260 | IK20: 45261 | IL20: 45262 | IM20: 45263 | IN20: 45264 | IO20: 45265 | IP20: 45266 | IQ20: 45267 | IR20: 45268 | IS20: 45269 | IT20: 45270 | IU20: 45271 | IV20: 45272 | IW20: 45273 | IX20: 45274 | IY20: 45275 | IZ20: 45276 | JA20: 45277 | JB20: 45278 | JC20: 45279 | JD20: 45280 | JE20: 45281 | JF20: 45282 | JG20: 45283 | JH20: 45284 | JI20: 45285 | JJ20: 45286 | JK20: 45287 | JL20: 45288 | JM20: 45289 | JN20: 45290 | JO20: 45291 | JP20: 45292 | JQ20: 45293 | JR20: 45294 | JS20: 45295 | JT20: 45296 | JU20: 45297 | JV20: 45298 | JW20: 45299 | JX20: 45300 | JY20: 45301 | JZ20: 45302 | KA20: 45303 | KB20: 45304 | KC20: 45305 | KD20: 45306 | KE20: 45307 | KF20: 45308 | KG20: 45309 | KH20: 45310 | KI20: 45311 | KJ20: 45312 | KK20: 45313 | KL20: 45314 | KM20: 45315 | KN20: 45316 | KO20: 45317 | KP20: 45318 | KQ20: 45319 | KR20: 45320 | KS20: 45321 | KT20: 45322 | KU20: 45323 | KV20: 45324 | KW20: 45325 | KX20: 45326 | KY20: 45327 | KZ20: 45328 | LA20: 45329 | LB20: 45330 | LC20: 45331 | LD20: 45332 | LE20: 45333 | LF20: 45334 | LG20: 45335 | LH20: 45336 | LI20: 45337 | LJ20: 45338 | LK20: 45339 | LL20: 45340 | LM20: 45341 | LN20: 45342 | LO20: 45343 | LP20: 45344 | LQ20: 45345 | LR20: 45346 | LS20: 45347 | LT20: 45348 | LU20: 45349 | LV20: 45350 | LW20: 45351 | LX20: 45352 | LY20: 45353 | LZ20: 45354 | MA20: 45355 | MB20: 45356 | MC20: 45357 | MD20: 45358 | ME20: 45359 | MF20: 45360 | MG20: 45361 | MH20: 45362 | MI20: 45363 | MJ20: 45364 | MK20: 45365 | ML20: 45366 | MM20: 45367 | MN20: 45368 | MO20: 45369 | MP20: 45370 | MQ20: 45371 | MR20: 45372 | MS20: 45373 | MT20: 45374 | MU20: 45375 | MV20: 45376 | MW20: 45377 | MX20: 45378 | MY20: 45379 | MZ20: 45380 | NA20: 45381 | NB20: 45382 | NC20: 45383 | ND20: 45384 | NE20: 45385 | NF20: 45386 | NG20: 45387 | NH20: 45388 | NI20: 45389 | NJ20: 45390 | NK20: 45391 | NL20: 45392 | NM20: 45393 | NN20: 45394 | NO20: 45395 | NP20: 45396 | NQ20: 45397 | NR20: 45398 | NS20: 45399 | NT20: 45400 | NU20: 45401 | NV20: 45402 | NW20: 45403 | NX20: 45404 | NY20: 45405 | NZ20: 45406 | OA20: 45407 | OB20: 45408 | OC20: 45409 | OD20: 45410 | OE20: 45411 | OF20: 45412 | OG20: 45413 | OH20: 45414 | OI20: 45415 | OJ20: 45416 | OK20: 45417 | OL20: 45418 | OM20: 45419 | ON20: 45420 | OO20: 45421 | OP20: 45422 | OQ20: 45423 | OR20: 45424 | OS20: 45425 | OT20: 45426 | OU20: 45427 | OV20: 45428 | OW20: 45429 | OX20: 45430 | OY20: 45431 | OZ20: 45432 | PA20: 45433 | PB20: 45434 | PC20: 45435 | PD20: 45436 | PE20: 45437 | PF20: 45438 | PG20: 45439 | PH20: 45440 | PI20: 45441 | PJ20: 45442 | PK20: 45443 | PL20: 45444 | PM20: 45445 | PN20: 45446 | PO20: 45447 | PP20: 45448 | PQ20: 45449 | PR20: 45450 | PS20: 45451 | PT20: 45452 | PU20: 45453 | PV20: 45454 | PW20: 45455 | PX20: 45456 | PY20: 45457 | PZ20: 45458 | QA20: 45459 | QB20: 45460 | QC20: 45461 | QD20: 45462 | QE20: 45463 | QF20: 45464 | QG20: 45465 | QH20: 45466 | QI20: 45467 | QJ20: 45468 | QK20: 45469 | QL20: 45470 | QM20: 45471 | QN20: 45472 | QO20: 45473 | QP20: 45474 | QQ20: 45475 | QR20: 45476 | QS20: 45477 | QT20: 45478 | QU20: 45479 | QV20: 45480 | QW20: 45481 | QX20: 45482 | QY20: 45483 | QZ20: 45484 | RA20: 45485 | RB20: 45486 | RC20: 45487 | RD20: 45488 | RE20: 45489 | RF20: 45490 | RG20: 45491 | RH20: 45492 | RI20: 45493 | RJ20: 45494 | RK20: 45495 | RL20: 45496 | RM20: 45497 | RN20: 45498 | RO20: 45499 | RP20: 45500 | RQ20: 45501 | RR20: 45502 | RS20: 45503 | RT20: 45504 | RU20: 45505 | RV20: 45506 | RW20: 45507 | RX20: 45508 | RY20: 45509 | RZ20: 45510 | SA20: 45511 | SB20: 45512 | SC20: 45513 | SD20: 45514 | SE20: 45515 | SF20: 45516 | SG20: 45517 | SH20: 45518 | SI20: 45519 | SJ20: 45520 | SK20: 45521 | SL20: 45522 | SM20: 45523 | SN20: 45524 | SO20: 45525 | SP20: 45526 | SQ20: 45527 | SR20: 45528 | SS20: 45529 | ST20: 45530 | SU20: 45531 | SV20: 45532 | SW20: 45533 | SX20: 45534 | SY20: 45535 | SZ20: 45536 | TA20: 45537 | TB20: 45538 | TC20: 45539 | TD20: 45540 | TE20: 45541 | TF20: 45542 | TG20: 45543 | TH20: 45544 | TI20: 45545 | TJ20: 45546 | TK20: 45547 | TL20: 45548 | TM20: 45549 | TN20: 45550 | TO20: 45551 | TP20: 45552 | TQ20: 45553 | TR20: 45554 | TS20: 45555 | TT20: 45556 | TU20: 45557 | TV20: 45558 | TW20: 45559 | TX20: 45560 | TY20: 45561 | TZ20: 45562 | UA20: 45563 | UB20: 45564 | UC20: 45565 | UD20: 45566 | UE20: 45567 | UF20: 45568 | UG20: 45569 | UH20: 45570 | UI20: 45571 | UJ20: 45572 | UK20: 45573 | UL20: 45574 | UM20: 45575 | UN20: 45576 | UO20: 45577 | UP20: 45578 | UQ20: 45579 | UR20: 45580 | US20: 45581 | UT20: 45582 | UU20: 45583 | UV20: 45584 | UW20: 45585 | UX20: 45586 | UY20: 45587 | UZ20: 45588 | VA20: 45589 | VB20: 45590 | VC20: 45591 | VD20: 45592 | VE20: 45593 | VF20: 45594 | VG20: 45595 | VH20: 45596 | VI20: 45597 | VJ20: 45598 | VK20: 45599 | VL20: 45600 | VM20: 45601 | VN20: 45602 | VO20: 45603 | VP20: 45604 | VQ20: 45605 | VR20: 45606 | VS20: 45607 | VT20: 45608 | VU20: 45609 | VV20: 45610 | VW20: 45611 | VX20: 45612 | VY20: 45613 | VZ20: 45614 | WA20: 45615 | WB20: 45616 | WC20: 45617 | WD20: 45618 | WE20: 45619 | WF20: 45620 | WG20: 45621 | WH20: 45622 | WI20: 45623 | WJ20: 45624 | WK20: 45625 | WL20: 45626 | WM20: 45627 | WN20: 45628 | WO20: 45629 | WP20: 45630 | WQ20: 45631 | WR20: 45632 | WS20: 45633 | WT20: 45634 | WU20: 45635 | WV20: 45636 | WW20: 45637 | WX20: 45638 | WY20: 45639 | WZ20: 45640 | XA20: 45641 | XB20: 45642 | XC20: 45643 | XD20: 45644 | XE20: 45645 | XF20: 45646 | XG20: 45647 | XH20: 45648 | XI20: 45649 | XJ20: 45650 | XK20: 45651 | XL20: 45652 | XM20: 45653 | XN20: 45654 | XO20: 45655 | XP20: 45656 | XQ20: 45657
B22: Cups to sell | C22: 5 | D22: 10 | E22: 15 | F22: 15 | G22: 15 | H22: 14 | I22: 10 | J22: =C22 -> 5 | K22: =D22 -> 10 | L22: =E22 -> 15 | M22: =F22 -> 15 | N22: =G22 -> 15 | O22: =H22 -> 14 | P22: =I22 -> 10 | Q22: =J22 -> 5 | ... XQ22: =XJ22 -> 10
B23: Cups to sell with factor | C23: =C22*$C$15 -> 42.5 | D23: =D22*$C$15 -> 85 | E23: =E22*$C$15 -> 127.5 | F23: =F22*$C$15 -> 127.5 | G23: =G22*$C$15 -> 127.5 | H23: =H22*$C$15 -> 119 | I23: =I22*$C$15 -> 85 | J23: =J22*$C$15 -> 42.5 | ... XQ23: =XQ22*$C$15 -> 85
B24: Sell at discount | C24: 10 | D24: 10 | E24: 10 | F24: 10 | G24: 10 | H24: 0 | I24: 0 | J24: 20 | K24: 20 | L24: 20 | M24: 20 | N24: 20 | O24: 0 | P24: 0 | Q24: =J24 -> 20 | R24: =K24 -> 20 | S24: =L24 -> 20 | T24: =M24 -> 20 | U24: =N24 -> 20 | V24: =O24 -> 0 | W24: =P24 -> 0 | X24: =Q24 -> 20 | ... XQ24: =XJ24 -> 20
B25: Cost of coffee | C25: =-SUM(C23+C24)*$D$6 -> -743.54875 | D25: =-SUM(D23+D24)*$D$6 -> -1345.4692 | E25: =-SUM(E23+E24)*$D$6 -> -1947.3896 | F25: =-SUM(F23+F24)*$D$6 -> -1947.3896 | G25: =-SUM(G23+G24)*$D$6 -> -1947.3896 | H25: =-SUM(H23+H24)*$D$6 -> -1685.3772 | I25: =-SUM(I23+I24)*$D$6 -> -1203.8408 | J25: =-SUM(J23+J24)*$D$6 -> -885.17708 | ... XQ25: =-SUM(XQ23+XQ24)*$D$6 -> -1487.0975
B26: Sugar | C26: =-C23*$C$12*$C$13 -> -9.5625 | D26: =-D23*$C$12*$C$13 -> -19.125 | E26: =-E23*$C$12*$C$13 -> -28.6875 | F26: =-F23*$C$12*$C$13 -> -28.6875 | G26: =-G23*$C$12*$C$13 -> -28.6875 | H26: =-H23*$C$12*$C$13 -> -26.775 | I26: =-I23*$C$12*$C$13 -> -19.125 | J26: =-J23*$C$12*$C$13 -> -9.5625 | ... XQ26: =-XQ23*$C$12*$C$13 -> -19.125
B27: Income | C27: =C23*$C$8 + $C$9*C24 -> 1600 | D27: =D23*$C$8 + $C$9*D24 -> 2960 | E27: =E23*$C$8 + $C$9*E24 -> 4320 | F27: =F23*$C$8 + $C$9*F24 -> 4320 | G27: =G23*$C$8 + $C$9*G24 -> 4320 | H27: =H23*$C$8 + $C$9*H24 -> 3808 | I27: =I23*$C$8 + $C$9*I24 -> 2720 | J27: =J23*$C$8 + $C$9*J24 -> 1840 | ... XQ27: =XQ23*$C$8 + $C$9*XQ24 -> 3200
B28: Coffee profit | C28: =C27+C26+C25 -> 846.88875 | D28: =D27+D26+D25 -> 1595.4058 | E28: =E27+E26+E25 -> 2343.9229 | F28: =F27+F26+F25 -> 2343.9229 | G28: =G27+G26+G25 -> 2343.9229 | H28: =H27+H26+H25 -> 2095.8478 | I28: =I27+I26+I25 -> 1497.0342 | J28: =J27+J26+J25 -> 945.26042 | ... XQ28: =XQ27+XQ26+XQ25 -> 1693.7775
B33: Monthly view
B34: Months | C34: 45046 | D34: 45077 | E34: 45107 | F34: 45138 | G34: 45169 | H34: 45199 | I34: 45230 | J34: 45260 | K34: 45291 | L34: 45322 | M34: 45351 | N34: 45382 | O34: 45412 | P34: 45443 | Q34: 45473 | R34: 45504 | S34: 45535 | T34: 45565 | U34: 45596 | V34: 45626 | W34: 45657
B35: Cups to sell | C35: =SUMIF('Coffee and food'!$C$18:$XQ$18,"="&'Coffee and food'!C34,'Coffee and food'!$C$23:$XQ$23) -> 2856 | D35: =SUMIF('Coffee and food'!$C$18:$XQ$18,"="&'Coffee and food'!D34,'Coffee and food'!$C$23:$XQ$23) -> 3111 | E35: =SUMIF('Coffee and food'!$C$18:$XQ$18,"="&'Coffee and food'!E34,'Coffee and food'!$C$23:$XQ$23) -> 3111 | F35: =SUMIF('Coffee and food'!$C$18:$XQ$18,"="&'Coffee and food'!F34,'Coffee and food'!$C$23:$XQ$23) -> 3102.5 | G35: =SUMIF('Coffee and food'!$C$18:$XQ$18,"="&'Coffee and food'!G34,'Coffee and food'!$C$23:$XQ$23) -> 3196 | H35: =SUMIF('Coffee and food'!$C$18:$XQ$18,"="&'Coffee and food'!H34,'Coffee and food'!$C$23:$XQ$23) -> 3102.5 | I35: =SUMIF('Coffee and food'!$C$18:$XQ$18,"="&'Coffee and food'!I34,'Coffee and food'!$C$23:$XQ$23) -> 3068.5 | J35: =SUMIF('Coffee and food'!$C$18:$XQ$18,"="&'Coffee and food'!J34,'Coffee and food'!$C$23:$XQ$23) -> 3111 | ... W35: =SUMIF('Coffee and food'!$C$18:$XQ$18,"="&'Coffee and food'!W34,'Coffee and food'!$C$23:$XQ$23) -> 3068.5
B36: Cups per day | C36: =C35/30 -> 95.2 | D36: =D35/30 -> 103.7 | E36: =E35/30 -> 103.7 | F36: =F35/30 -> 103.41667 | G36: =G35/30 -> 106.53333 | H36: =H35/30 -> 103.41667 | I36: =I35/30 -> 102.28333 | J36: =J35/30 -> 103.7 | ... W36: =W35/30 -> 102.28333
B37: =B25 -> Cost of coffee | C37: =SUMIF('Coffee and food'!$C$18:$XQ$18,"="&'Coffee and food'!C34,'Coffee and food'!$C$25:$XQ$25) -> -45406.044 | D37: =SUMIF('Coffee and food'!$C$18:$XQ$18,"="&'Coffee and food'!D34,'Coffee and food'!$C$25:$XQ$25) -> -50575.478 | E37: =SUMIF('Coffee and food'!$C$18:$XQ$18,"="&'Coffee and food'!E34,'Coffee and food'!$C$25:$XQ$25) -> -50292.221 | F37: =SUMIF('Coffee and food'!$C$18:$XQ$18,"="&'Coffee and food'!F34,'Coffee and food'!$C$25:$XQ$25) -> -49888.58 | G37: =SUMIF('Coffee and food'!$C$18:$XQ$18,"="&'Coffee and food'!G34,'Coffee and food'!$C$25:$XQ$25) -> -51779.319 | H37: =SUMIF('Coffee and food'!$C$18:$XQ$18,"="&'Coffee and food'!H34,'Coffee and food'!$C$25:$XQ$25) -> -49888.58 | I37: =SUMIF('Coffee and food'!$C$18:$XQ$18,"="&'Coffee and food'!I34,'Coffee and food'!$C$25:$XQ$25) -> -49690.301 | J37: =SUMIF('Coffee and food'!$C$18:$XQ$18,"="&'Coffee and food'!J34,'Coffee and food'!$C$25:$XQ$25) -> -50292.221 | ... W37: =SUMIF('Coffee and food'!$C$18:$XQ$18,"="&'Coffee and food'!W34,'Coffee and food'!$C$25:$XQ$25) -> -49690.301
B38: =B26 -> Sugar | C38: =SUMIF('Coffee and food'!$C$18:$XQ$18,"="&'Coffee and food'!C34,'Coffee and food'!$C$26:$XQ$26) -> -642.6 | D38: =SUMIF('Coffee and food'!$C$18:$XQ$18,"="&'Coffee and food'!D34,'Coffee and food'!$C$26:$XQ$26) -> -699.975 | E38: =SUMIF('Coffee and food'!$C$18:$XQ$18,"="&'Coffee and food'!E34,'Coffee and food'!$C$26:$XQ$26) -> -699.975 | F38: =SUMIF('Coffee and food'!$C$18:$XQ$18,"="&'Coffee and food'!F34,'Coffee and food'!$C$26:$XQ$26) -> -698.0625 | G38: =SUMIF('Coffee and food'!$C$18:$XQ$18,"="&'Coffee and food'!G34,'Coffee and food'!$C$26:$XQ$26) -> -719.1 | H38: =SUMIF('Coffee and food'!$C$18:$XQ$18,"="&'Coffee and food'!H34,'Coffee and food'!$C$26:$XQ$26) -> -698.0625 | I38: =SUMIF('Coffee and food'!$C$18:$XQ$18,"="&'Coffee and food'!I34,'Coffee and food'!$C$26:$XQ$26) -> -690.4125 | J38: =SUMIF('Coffee and food'!$C$18:$XQ$18,"="&'Coffee and food'!J34,'Coffee and food'!$C$26:$XQ$26) -> -699.975 | ... W38: =SUMIF('Coffee and food'!$C$18:$XQ$18,"="&'Coffee and food'!W34,'Coffee and food'!$C$26:$XQ$26) -> -690.4125
B39: =B27 -> Income | C39: =SUMIF('Coffee and food'!$C$18:$XQ$18,"="&'Coffee and food'!C34,'Coffee and food'!$C$27:$XQ$27) -> 99792 | D39: =SUMIF('Coffee and food'!$C$18:$XQ$18,"="&'Coffee and food'!D34,'Coffee and food'!$C$27:$XQ$27) -> 110592 | E39: =SUMIF('Coffee and food'!$C$18:$XQ$18,"="&'Coffee and food'!E34,'Coffee and food'!$C$27:$XQ$27) -> 110112 | F39: =SUMIF('Coffee and food'!$C$18:$XQ$18,"="&'Coffee and food'!F34,'Coffee and food'!$C$27:$XQ$27) -> 109360 | G39: =SUMIF('Coffee and food'!$C$18:$XQ$18,"="&'Coffee and food'!G34,'Coffee and food'!$C$27:$XQ$27) -> 113312 | H39: =SUMIF('Coffee and food'!$C$18:$XQ$18,"="&'Coffee and food'!H34,'Coffee and food'!$C$27:$XQ$27) -> 109360 | I39: =SUMIF('Coffee and food'!$C$18:$XQ$18,"="&'Coffee and food'!I34,'Coffee and food'!$C$27:$XQ$27) -> 108752 | J39: =SUMIF('Coffee and food'!$C$18:$XQ$18,"="&'Coffee and food'!J34,'Coffee and food'!$C$27:$XQ$27) -> 110112 | ... W39: =SUMIF('Coffee and food'!$C$18:$XQ$18,"="&'Coffee and food'!W34,'Coffee and food'!$C$27:$XQ$27) -> 108752
B40: =B28 -> Coffee profit | C40: =SUMIF('Coffee and food'!$C$18:$XQ$18,"="&'Coffee and food'!C34,'Coffee and food'!$C$28:$XQ$28) -> 53743.356 | D40: =SUMIF('Coffee and food'!$C$18:$XQ$18,"="&'Coffee and food'!D34,'Coffee and food'!$C$28:$XQ$28) -> 59316.547 | E40: =SUMIF('Coffee and food'!$C$18:$XQ$18,"="&'Coffee and food'!E34,'Coffee and food'!$C$28:$XQ$28) -> 59119.804 | F40: =SUMIF('Coffee and food'!$C$18:$XQ$18,"="&'Coffee and food'!F34,'Coffee and food'!$C$28:$XQ$28) -> 58773.357 | G40: =SUMIF('Coffee and food'!$C$18:$XQ$18,"="&'Coffee and food'!G34,'Coffee and food'!$C$28:$XQ$28) -> 60813.581 | H40: =SUMIF('Coffee and food'!$C$18:$XQ$18,"="&'Coffee and food'!H34,'Coffee and food'!$C$28:$XQ$28) -> 58773.357 | I40: =SUMIF('Coffee and food'!$C$18:$XQ$18,"="&'Coffee and food'!I34,'Coffee and food'!$C$28:$XQ$28) -> 58371.287 | J40: =SUMIF('Coffee and food'!$C$18:$XQ$18,"="&'Coffee and food'!J34,'Coffee and food'!$C$28:$XQ$28) -> 59119.804 | ... W40: =SUMIF('Coffee and food'!$C$18:$XQ$18,"="&'Coffee and food'!W34,'Coffee and food'!$C$28:$XQ$28) -> 58371.287
B42: How much to buy of everything - Weekly view
C43: Total
B44: Beans | C44: =SUM(C23:K23)*'Coffee and food'!C3 -> 20196 | D44: =C44/1000 -> 20.196 | E44: 1 kg pack of coffee beans | G44: =D44*265 -> 5351.94
B45: Milk | C45: =SUM(C23:E23)*'Coffee and food'!C4 -> 68850 | D45: =C45/1000 -> 68.85 | E45: Liters of milk | G45: =D45*(11.3) -> 778.005
G46: =SUM(G44:G45) -> 6129.945
B47: When will the cups run-out?
B48: Total cups | C48: =Inputs!D57 -> 6000
B49: Month | C49: 1 | D49: =C49+1 -> 2 | E49: =D49+1 -> 3 | F49: =E49+1 -> 4 | G49: =F49+1 -> 5 | H49: =G49+1 -> 6 | I49: =H49+1 -> 7 | J49: =I49+1 -> 8 | K49: =J49+1 -> 9
...

Sheet Projections
D1: 1 | E1: =D1+1 -> 2 | F1: =E1+1 -> 3 | G1: =F1+1 -> 4 | H1: =G1+1 -> 5 | I1: =H1+1 -> 6 | J1: =I1+1 -> 7 | K1: =J1+1 -> 8 | L1: =K1+1 -> 9 | ... Y1: =X1+1 -> 22
D2: 44986 | E2: 45017 | F2: 45047 | G2: 45078 | H2: 45108 | I2: 45139 | J2: 45170 | K2: 45200 | L2: 45231 | M2: 45261 | N2: 45292 | O2: 45323 | P2: 45352 | Q2: 45383 | R2: 45413 | S2: 45444 | T2: 45474 | U2: 45505 | V2: 45536 | W2: 45566 | X2: 45597 | Y2: 45627
A4: Once-off costs | D4: =-Inputs!C32 +Inputs!C13 -> -151224.88
A5: Recurring costs | E5: =-Inputs!$C$43 -> -38300 | F5: =-Inputs!$C$43 -> -38300 | G5: =-Inputs!$C$43 -> -38300 | H5: =-Inputs!$C$43 -> -38300 | I5: =-Inputs!$C$43 -> -38300 | J5: =-Inputs!$C$43 -> -38300 | K5: =-Inputs!$C$43 -> -38300 | L5: =-Inputs!$C$43 -> -38300 | ... Y5: =-Inputs!$C$43 -> -38300
A6: Later occuring costs
A8: Coffee
A9: Cost of coffee | E9: ='Coffee and food'!C37 -> -45406.044 | F9: ='Coffee and food'!D37 -> -50575.478 | G9: ='Coffee and food'!E37 -> -50292.221 | H9: ='Coffee and food'!F37 -> -49888.58 | I9: ='Coffee and food'!G37 -> -51779.319 | J9: ='Coffee and food'!H37 -> -49888.58 | K9: ='Coffee and food'!I37 -> -49690.301 | L9: ='Coffee and food'!J37 -> -50292.221 | ... Y9: ='Coffee and food'!W37 -> -49690.301
A10: Income from coffee | E10: ='Coffee and food'!C39 -> 99792 | F10: ='Coffee and food'!D39 -> 110592 | G10: ='Coffee and food'!E39 -> 110112 | H10: ='Coffee and food'!F39 -> 109360 | I10: ='Coffee and food'!G39 -> 113312 | J10: ='Coffee and food'!H39 -> 109360 | K10: ='Coffee and food'!I39 -> 108752 | L10: ='Coffee and food'!J39 -> 110112 | ... Y10: ='Coffee and food'!W39 -> 108752
A11: Coffee profit | E11: ='Coffee and food'!C40 -> 53743.356 | F11: ='Coffee and food'!D40 -> 59316.547 | G11: ='Coffee and food'!E40 -> 59119.804 | H11: ='Coffee and food'!F40 -> 58773.357 | I11: ='Coffee and food'!G40 -> 60813.581 | J11: ='Coffee and food'!H40 -> 58773.357 | K11: ='Coffee and food'!I40 -> 58371.287 | L11: ='Coffee and food'!J40 -> 59119.804 | ... Y11: ='Coffee and food'!W40 -> 58371.287
A13: Food
A14: Cost of food | E14: ='Coffee and food'!C64 -> 2000 | F14: ='Coffee and food'!D64 -> 3000 | G14: ='Coffee and food'!E64 -> 5250 | H14: ='Coffee and food'!F64 -> 5250 | I14: ='Coffee and food'!G64 -> 5250 | J14: ='Coffee and food'!H64 -> 5250 | K14: ='Coffee and food'!I64 -> 5250 | L14: ='Coffee and food'!J64 -> 5250 | ... Y14: ='Coffee and food'!W64 -> 5250
A15: Income from food | E15: ='Coffee and food'!C65 -> 3800 | F15: ='Coffee and food'!D65 -> 5700 | G15: ='Coffee and food'!E65 -> 9975 | H15: ='Coffee and food'!F65 -> 9975 | I15: ='Coffee and food'!G65 -> 9975 | J15: ='Coffee and food'!H65 -> 9975 | K15: ='Coffee and food'!I65 -> 9975 | L15: ='Coffee and food'!J65 -> 9975 | ... Y15: ='Coffee and food'!W65 -> 9975
A16: Food profit | E16: ='Coffee and food'!C66 -> 1800 | F16: ='Coffee and food'!D66 -> 2700 | G16: ='Coffee and food'!E66 -> 4725 | H16: ='Coffee and food'!F66 -> 4725 | I16: ='Coffee and food'!G66 -> 4725 | J16: ='Coffee and food'!H66 -> 4725 | K16: ='Coffee and food'!I66 -> 4725 | L16: ='Coffee and food'!J66 -> 4725 | ... Y16: ='Coffee and food'!W66 -> 4725
A18: Total sales income | D18: =D11+D16 -> 0 | E18: =E11+E16 -> 55543.356 | F18: =F11+F16 -> 62016.547 | G18: =G11+G16 -> 63844.804 | H18: =H11+H16 -> 63498.357 | I18: =I11+I16 -> 65538.581 | J18: =J11+J16 -> 63498.357 | K18: =K11+K16 -> 63096.287 | ... Y18: =Y11+Y16 -> 63096.287
A19: Yoco sales cost | D19: =Inputs!$C$46*Projections!D18 -> 0 | E19: =-Inputs!$C$46*Projections!E18 -> -1884.3084 | F19: =-Inputs!$C$46*Projections!F18 -> -2103.9114 | G19: =-Inputs!$C$46*Projections!G18 -> -2165.935 | H19: =-Inputs!$C$46*Projections!H18 -> -2154.1818 | I19: =-Inputs!$C$46*Projections!I18 -> -2223.3964 | J19: =-Inputs!$C$46*Projections!J18 -> -2154.1818 | K19: =-Inputs!$C$46*Projections!K18 -> -2140.5415 | L19: =-Inputs!$C$46*Projections!L18 -> -2165.935 | ... Y19: =-Inputs!$C$46*Projections!Y18 -> -2140.5415
A21: Total Net income | D21: =D4+D5+D6 + D18 + D19 -> -151224.88 | E21: =E4+E5+E6 + E18 + E19 -> 15359.048 | F21: =F4+F5+F6 + F18 + F19 -> 21612.636 | G21: =G4+G5+G6 + G18 + G19 -> 23378.869 | H21: =H4+H5+H6 + H18 + H19 -> 23044.175 | I21: =I4+I5+I6 + I18 + I19 -> 25015.185 | J21: =J4+J5+J6 + J18 + J19 -> 23044.175 | K21: =K4+K5+K6 + K18 + K19 -> 22655.745 | ... Y21: =Y4+Y5+Y6 + Y18 + Y19 -> 22655.745
A22: Discount | D22: =D21*(1+Inputs!$C$47)^(-D1/12) -> -150611.27 | E22: =E21*(1+Inputs!$C$47)^(-E1/12) -> 15234.659 | F22: =F21*(1+Inputs!$C$47)^(-F1/12) -> 21350.616 | G22: =G21*(1+Inputs!$C$47)^(-G1/12) -> 23001.724 | H22: =H21*(1+Inputs!$C$47)^(-H1/12) -> 22580.435 | I22: =I21*(1+Inputs!$C$47)^(-I1/12) -> 24412.321 | J22: =J21*(1+Inputs!$C$47)^(-J1/12) -> 22397.562 | K22: =K21*(1+Inputs!$C$47)^(-K1/12) -> 21930.683 | ... Y22: =Y21*(1+Inputs!$C$47)^(-Y1/12) -> 20717.212
A23: Cumulative sum | D23: =SUM($D$22:D22) -> -150611.27 | E23: =SUM($D$22:E22) -> -135376.61 | F23: =SUM($D$22:F22) -> -114026 | G23: =SUM($D$22:G22) -> -91024.271 | H23: =SUM($D$22:H22) -> -68443.837 | I23: =SUM($D$22:I22) -> -44031.516 | J23: =SUM($D$22:J22) -> -21633.954 | K23: =SUM($D$22:K22) -> 296.72882 | ... Y23: =SUM($D$22:Y22) -> 307124.43
A25: Goal seek | D25: 0
D26: =D25+D23 -> -150611.27
A29: Start-up costs
A30: Coffeee | B30: 10000 | C30: Once-off
A31: Coffee cups included
A32: Sugar
A33: Decorations
A34: Marketing

Sheet Graphs
A1: 1. Coffee sales
B2: Date | C2: ='Coffee and food'!C20 -> 45019 | D2: ='Coffee and food'!D20 -> 45020 | E2: ='Coffee and food'!E20 -> 45021 | F2: ='Coffee and food'!F20 -> 45022 | G2: ='Coffee and food'!G20 -> 45023 | H2: ='Coffee and food'!H20 -> 45024 | I2: ='Coffee and food'!I20 -> 45025 | J2: ='Coffee and food'!J20 -> 45026 | ... XQ2: ='Coffee and food'!XQ20 -> 45657
B3: Cups to sell | C3: ='Coffee and food'!C23 -> 42.5 | D3: ='Coffee and food'!D23 -> 85 | E3: ='Coffee and food'!E23 -> 127.5 | F3: ='Coffee and food'!F23 -> 127.5 | G3: ='Coffee and food'!G23 -> 127.5 | H3: ='Coffee and food'!H23 -> 119 | I3: ='Coffee and food'!I23 -> 85 | J3: ='Coffee and food'!J23 -> 42.5 | ... XQ3: ='Coffee and food'!XQ23 -> 85
A25: 2. Profit
B26: Date | C26: =Projections!D2 -> 44986 | D26: =Projections!E2 -> 45017 | E26: =Projections!F2 -> 45047 | F26: =Projections!G2 -> 45078 | G26: =Projections!H2 -> 45108 | H26: =Projections!I2 -> 45139 | I26: =Projections!J2 -> 45170 | J26: =Projections!K2 -> 45200 | ... X26: =Projections!Y2 -> 45627
B27: Coffe profit | C27: 0 | D27: =Projections!E11 -> 53743.356 | E27: =Projections!F11 -> 59316.547 | F27: =Projections!G11 -> 59119.804 | G27: =Projections!H11 -> 58773.357 | H27: =Projections!I11 -> 60813.581 | I27: =Projections!J11 -> 58773.357 | J27: =Projections!K11 -> 58371.287 | K27: =Projections!L11 -> 59119.804 | ... Y27: =Projections!Z11 -> 0
B28: Food profit | C28: 0 | D28: =Projections!E16 -> 1800 | E28: =Projections!F16 -> 2700 | F28: =Projections!G16 -> 4725 | G28: =Projections!H16 -> 4725 | H28: =Projections!I16 -> 4725 | I28: =Projections!J16 -> 4725 | J28: =Projections!K16 -> 4725 | K28: =Projections!L16 -> 4725 | ... Y28: =Projections!Z16 -> 0
A50: 3. Total Profit
B51: Date | C51: =Projections!D2 -> 44986 | D51: =Projections!E2 -> 45017 | E51: =Projections!F2 -> 45047 | F51: =Projections!G2 -> 45078 | G51: =Projections!H2 -> 45108 | H51: =Projections!I2 -> 45139 | I51: =Projections!J2 -> 45170 | J51: =Projections!K2 -> 45200 | ... X51: =Projections!Y2 -> 45627
B52: Profit | C52: =Projections!D21 -> -151224.88 | D52: =Projections!E21 -> 15359.048 | E52: =Projections!F21 -> 21612.636 | F52: =Projections!G21 -> 23378.869 | G52: =Projections!H21 -> 23044.175 | H52: =Projections!I21 -> 25015.185 | I52: =Projections!J21 -> 23044.175 | J52: =Projections!K21 -> 22655.745 | ... X52: =Projections!Y21 -> 22655.745

Sheet Food Prices 
E1: 0.45
A2: Food items | B2: Price ex Vat | C2: Vat | D2: Price | E2: Mark-up % | F2: Mark-up Rand | H2: Final Price
A3: Plain crossaint | B3: 14.85 | C3: =B3*0.15 -> 2.2275 | D3: =SUM(B3:C3) -> 17.0775 | E3: =$E$1 -> 0.45 | F3: =D3*(1+E3) -> 24.762375 | H3: 23
A4: Ham and cheese crossaint | B4: 21.5 | C4: =B4*0.15 -> 3.225 | D4: =SUM(B4:C4) -> 24.725 | E4: =$E$1 -> 0.45 | F4: =D4*(1+E4) -> 35.85125 | H4: 40
A5: Cheese and Tomato crosssaint | B5: 24.4 | C5: =B5*0.15 -> 3.66 | D5: =SUM(B5:C5) -> 28.06 | E5: =$E$1 -> 0.45 | F5: =D5*(1+E5) -> 40.687 | H5: 40
A6: Mini Choclate crossaint | B6: 12 | C6: =B6*0.15 -> 1.8 | D6: =SUM(B6:C6) -> 13.8 | E6: =$E$1 -> 0.45 | F6: =D6*(1+E6) -> 20.01 | H6: 20
A7: Custard container | B7: 20.6 | C7: =B7*0.15 -> 3.09 | D7: =SUM(B7:C7) -> 23.69 | E7: =$E$1 -> 0.45 | F7: =D7*(1+E7) -> 34.3505 | H7: 35
A8: Brownies | B8: 20 | C8: =B8*0.15 -> 3 | D8: =SUM(B8:C8) -> 23 | E8: =$E$1 -> 0.45 | F8: =D8*(1+E8) -> 33.35 | H8: 30
A9: Oat Crunchies | B9: 15 | C9: =B9*0.15 -> 2.25 | D9: =SUM(B9:C9) -> 17.25 | E9: =$E$1 -> 0.45 | F9: =D9*(1+E9) -> 25.0125 | H9: 25
A10: Choclate squares | B10: 7.5 | C10: =B10*0.15 -> 1.125 | D10: =SUM(B10:C10) -> 8.625 | E10: =$E$1 -> 0.45 | F10: =D10*(1+E10) -> 12.50625 | H10: 15
A11: Pasteis de Nata | B11: 16 | C11: =B11*0.15 -> 2.4 | D11: =SUM(B11:C11) -> 18.4 | E11: =$E$1 -> 0.45 | F11: =D11*(1+E11) -> 26.68 | H11: 25
F12: =SUM(F3:F11) -> 253.20987 | H12: =SUM(H3:H11) -> 253
A14: =A2 -> Food items
A15: =A3 -> Plain crossaint | B15: =H3 -> 23
A16: =A4 -> Ham and cheese crossaint | B16: =H4 -> 40
A17: =A5 -> Cheese and Tomato crosssaint | B17: =H5 -> 40
A18: =A6 -> Mini Choclate crossaint | B18: =H6 -> 20
A19: =A7 -> Custard container | B19: =H7 -> 35
A20: =A8 -> Brownies | B20: =H8 -> 30
A21: =A9 -> Oat Crunchies | B21: =H9 -> 25
A22: =A10 -> Choclate squares | B22: =H10 -> 15
A23: =A11 -> Pasteis de Nata | B23: =H11 -> 25
